Workbook

Sheet Weekly_Cash_Flow_Summary
A1: 13-Week Rolling Cash Flow Forecast
A3: As of Date | B3: =Cash_Balance!E1 -> 46230 | F3: Week | G3: Week Start | H3: Week End | I3: Inflow(AR) | J3: Outflow(AP) | K3: Net Cash Flow | L3: Ending Bal | M3: Below Threshold?
A4: Beginning Cash | B4: =Cash_Balance!E2 -> 1938408 | F4: 1 | G4: =$B$3+(1-1)*7 -> 46230 | H4: =$B$3+(1-1)*7+6 -> 46236 | I4: =SUMPRODUCT((AR_detail!$L$2:$L$121>=G4)*(AR_detail!$L$2:$L$121<=H4)*(AR_detail!$J$2:$J$121<>"Collected")*AR_detail!$H$2:$H$121*AR_detail!$M$2:$M$121) -> 3161845 | J4: =SUMPRODUCT((AP_detail!$L$2:$L$101>=G4)*(AP_detail!$L$2:$L$101<=H4)*(AP_detail!$J$2:$J$101<>"Paid")*AP_detail!$H$2:$H$101) -> 1847500 | K4: =I4-J4 -> 1314345 | L4: =$B$4+K4 -> 3252753 | M4: =IF(L4<$B$5,"WARNING","OK") -> OK
A5: Min Cash Threshold | B5: =Cash_Balance!E3 -> 1500000 | F5: 2 | G5: =$B$3+(2-1)*7 -> 46237 | H5: =$B$3+(2-1)*7+6 -> 46243 | I5: =SUMPRODUCT((AR_detail!$L$2:$L$121>=G5)*(AR_detail!$L$2:$L$121<=H5)*(AR_detail!$J$2:$J$121<>"Collected")*AR_detail!$H$2:$H$121*AR_detail!$M$2:$M$121) -> 1260675 | J5: =SUMPRODUCT((AP_detail!$L$2:$L$101>=G5)*(AP_detail!$L$2:$L$101<=H5)*(AP_detail!$J$2:$J$101<>"Paid")*AP_detail!$H$2:$H$101) -> 1500500 | K5: =I5-J5 -> -239825 | L5: =L4+K5 -> 3012928 | M5: =IF(L5<$B$5,"WARNING","OK") -> OK
A6: Scenario | B6: Base | F6: 3 | G6: =$B$3+(3-1)*7 -> 46244 | H6: =$B$3+(3-1)*7+6 -> 46250 | I6: {=SUMPRODUCT((AR_detail!$L$2:$L$121>=G6)*(AR_detail!$L$2:$L$121<=H6)*(AR_detail!$J$2:$J$121<>"Collected")*AR_detail!$H$2:$H$121*AR_detail!$M$2:$M$121)} -> 1589265 | J6: =SUMPRODUCT((AP_detail!$L$2:$L$101>=G6)*(AP_detail!$L$2:$L$101<=H6)*(AP_detail!$J$2:$J$101<>"Paid")*AP_detail!$H$2:$H$101) -> 952500 | K6: =I6-J6 -> 636765 | L6: =L5+K6 -> 3649693 | M6: =IF(L6<$B$5,"WARNING","OK") -> OK
A7: Probability_Adjustment | B7: =INDEX($B$13:$B$15,MATCH($B$6,$A$13:$A$15,0)) -> 0 | F7: 4 | G7: =$B$3+(4-1)*7 -> 46251 | H7: =$B$3+(4-1)*7+6 -> 46257 | I7: =SUMPRODUCT((AR_detail!$L$2:$L$121>=G7)*(AR_detail!$L$2:$L$121<=H7)*(AR_detail!$J$2:$J$121<>"Collected")*AR_detail!$H$2:$H$121*AR_detail!$M$2:$M$121) -> 186915 | J7: =SUMPRODUCT((AP_detail!$L$2:$L$101>=G7)*(AP_detail!$L$2:$L$101<=H7)*(AP_detail!$J$2:$J$101<>"Paid")*AP_detail!$H$2:$H$101) -> 0 | K7: =I7-J7 -> 186915 | L7: =L6+K7 -> 3836608 | M7: =IF(L7<$B$5,"WARNING","OK") -> OK
A8: AR_Delay_Multiplier | B8: =INDEX($C$13:$C$15,MATCH($B$6,$A$13:$A$15,0)) -> 1 | F8: 5 | G8: =$B$3+(5-1)*7 -> 46258 | H8: =$B$3+(5-1)*7+6 -> 46264 | I8: {=SUMPRODUCT((AR_detail!$L$2:$L$121>=G8)*(AR_detail!$L$2:$L$121<=H8)*(AR_detail!$J$2:$J$121<>"Collected")*AR_detail!$H$2:$H$121*AR_detail!$M$2:$M$121)} -> 941010 | J8: {=SUMPRODUCT((AP_detail!$L$2:$L$101>=G8)*(AP_detail!$L$2:$L$101<=H8)*(AP_detail!$J$2:$J$101<>"Paid")*AP_detail!$H$2:$H$101)} -> 1485500 | K8: =I8-J8 -> -544490 | L8: =L7+K8 -> 3292118 | M8: =IF(L8<$B$5,"WARNING","OK") -> OK
A9: AP_Stretch_Multiplier | B9: =INDEX($D$13:$D$15,MATCH($B$6,$A$13:$A$15,0)) -> 1 | F9: 6 | G9: =$B$3+(6-1)*7 -> 46265 | H9: =$B$3+(6-1)*7+6 -> 46271 | I9: =SUMPRODUCT((AR_detail!$L$2:$L$121>=G9)*(AR_detail!$L$2:$L$121<=H9)*(AR_detail!$J$2:$J$121<>"Collected")*AR_detail!$H$2:$H$121*AR_detail!$M$2:$M$121) -> 50400 | J9: {=SUMPRODUCT((AP_detail!$L$2:$L$101>=G9)*(AP_detail!$L$2:$L$101<=H9)*(AP_detail!$J$2:$J$101<>"Paid")*AP_detail!$H$2:$H$101)} -> 132000 | K9: =I9-J9 -> -81600 | L9: =L8+K9 -> 3210518 | M9: =IF(L9<$B$5,"WARNING","OK") -> OK
F10: 7 | G10: =$B$3+(7-1)*7 -> 46272 | H10: =$B$3+(7-1)*7+6 -> 46278 | I10: =SUMPRODUCT((AR_detail!$L$2:$L$121>=G10)*(AR_detail!$L$2:$L$121<=H10)*(AR_detail!$J$2:$J$121<>"Collected")*AR_detail!$H$2:$H$121*AR_detail!$M$2:$M$121) -> 24750 | J10: =SUMPRODUCT((AP_detail!$L$2:$L$101>=G10)*(AP_detail!$L$2:$L$101<=H10)*(AP_detail!$J$2:$J$101<>"Paid")*AP_detail!$H$2:$H$101) -> 173000 | K10: =I10-J10 -> -148250 | L10: =L9+K10 -> 3062268 | M10: =IF(L10<$B$5,"WARNING","OK") -> OK
A11: Scenario assumption table (edit these to adjust the model) | F11: 8 | G11: =$B$3+(8-1)*7 -> 46279 | H11: =$B$3+(8-1)*7+6 -> 46285 | I11: =SUMPRODUCT((AR_detail!$L$2:$L$121>=G11)*(AR_detail!$L$2:$L$121<=H11)*(AR_detail!$J$2:$J$121<>"Collected")*AR_detail!$H$2:$H$121*AR_detail!$M$2:$M$121) -> 815475 | J11: =SUMPRODUCT((AP_detail!$L$2:$L$101>=G11)*(AP_detail!$L$2:$L$101<=H11)*(AP_detail!$J$2:$J$101<>"Paid")*AP_detail!$H$2:$H$101) -> 0 | K11: =I11-J11 -> 815475 | L11: =L10+K11 -> 3877743 | M11: =IF(L11<$B$5,"WARNING","OK") -> OK
A12: Scenario | B12: Prob Adj | C12: AR Delay Mult | D12: AP Stretch Mult | F12: 9 | G12: =$B$3+(9-1)*7 -> 46286 | H12: =$B$3+(9-1)*7+6 -> 46292 | I12: =SUMPRODUCT((AR_detail!$L$2:$L$121>=G12)*(AR_detail!$L$2:$L$121<=H12)*(AR_detail!$J$2:$J$121<>"Collected")*AR_detail!$H$2:$H$121*AR_detail!$M$2:$M$121) -> 0 | J12: =SUMPRODUCT((AP_detail!$L$2:$L$101>=G12)*(AP_detail!$L$2:$L$101<=H12)*(AP_detail!$J$2:$J$101<>"Paid")*AP_detail!$H$2:$H$101) -> 0 | K12: =I12-J12 -> 0 | L12: =L11+K12 -> 3877743 | M12: =IF(L12<$B$5,"WARNING","OK") -> OK
A13: Best | B13: 0.05 | C13: 0.5 | D13: 0.8 | F13: 10 | G13: =$B$3+(10-1)*7 -> 46293 | H13: =$B$3+(10-1)*7+6 -> 46299 | I13: =SUMPRODUCT((AR_detail!$L$2:$L$121>=G13)*(AR_detail!$L$2:$L$121<=H13)*(AR_detail!$J$2:$J$121<>"Collected")*AR_detail!$H$2:$H$121*AR_detail!$M$2:$M$121) -> 117450 | J13: =SUMPRODUCT((AP_detail!$L$2:$L$101>=G13)*(AP_detail!$L$2:$L$101<=H13)*(AP_detail!$J$2:$J$101<>"Paid")*AP_detail!$H$2:$H$101) -> 1033000 | K13: =I13-J13 -> -915550 | L13: =L12+K13 -> 2962193 | M13: =IF(L13<$B$5,"WARNING","OK") -> OK
A14: Base | B14: 0 | C14: 1 | D14: 1 | F14: 11 | G14: =$B$3+(11-1)*7 -> 46300 | H14: =$B$3+(11-1)*7+6 -> 46306 | I14: =SUMPRODUCT((AR_detail!$L$2:$L$121>=G14)*(AR_detail!$L$2:$L$121<=H14)*(AR_detail!$J$2:$J$121<>"Collected")*AR_detail!$H$2:$H$121*AR_detail!$M$2:$M$121) -> 0 | J14: =SUMPRODUCT((AP_detail!$L$2:$L$101>=G14)*(AP_detail!$L$2:$L$101<=H14)*(AP_detail!$J$2:$J$101<>"Paid")*AP_detail!$H$2:$H$101) -> 0 | K14: =I14-J14 -> 0 | L14: =L13+K14 -> 2962193 | M14: =IF(L14<$B$5,"WARNING","OK") -> OK
A15: Worst | B15: -0.15 | C15: 2 | D15: 1.8 | F15: 12 | G15: =$B$3+(12-1)*7 -> 46307 | H15: =$B$3+(12-1)*7+6 -> 46313 | I15: =SUMPRODUCT((AR_detail!$L$2:$L$121>=G15)*(AR_detail!$L$2:$L$121<=H15)*(AR_detail!$J$2:$J$121<>"Collected")*AR_detail!$H$2:$H$121*AR_detail!$M$2:$M$121) -> 0 | J15: =SUMPRODUCT((AP_detail!$L$2:$L$101>=G15)*(AP_detail!$L$2:$L$101<=H15)*(AP_detail!$J$2:$J$101<>"Paid")*AP_detail!$H$2:$H$101) -> 0 | K15: =I15-J15 -> 0 | L15: =L14+K15 -> 2962193 | M15: =IF(L15<$B$5,"WARNING","OK") -> OK
F16: 13 | G16: =$B$3+(13-1)*7 -> 46314 | H16: =$B$3+(13-1)*7+6 -> 46320 | I16: =SUMPRODUCT((AR_detail!$L$2:$L$121>=G16)*(AR_detail!$L$2:$L$121<=H16)*(AR_detail!$J$2:$J$121<>"Collected")*AR_detail!$H$2:$H$121*AR_detail!$M$2:$M$121) -> 0 | J16: =SUMPRODUCT((AP_detail!$L$2:$L$101>=G16)*(AP_detail!$L$2:$L$101<=H16)*(AP_detail!$J$2:$J$101<>"Paid")*AP_detail!$H$2:$H$101) -> 0 | K16: =I16-J16 -> 0 | L16: =L15+K16 -> 2962193 | M16: =IF(L16<$B$5,"WARNING","OK") -> OK

Sheet Cash_Balance
A1: Bank Account | B1: Ending Bal. | D1: As of Date | E1: 46230
A2: A bank (TWD) #58945 | B2: 589353 | D2: Beginning Cash | E2: =B7 -> 1938408
A3: B bank (TWD) #65084 | B3: 29472 | D3: Min Cash Threshold | E3: 1500000
A4: C bank (TWD) #20122 | B4: 60485
A5: D bank (TWD) #29060 | B5: 1038475
A6: E bank (TWD) #30582 | B6: 220623
B7: =SUM(B2:B6) -> 1938408
A10: <<<From TB>>>

Sheet AR_detail
A1: Invoice_ID | B1: Customer_Code | C1: Customer_Name | D1: Department | E1: Invoice_Date | F1: Due_Date | G1: Payment_Terms | H1: Amount | I1: Collection_Probability | J1: Status | K1: Autual_Collection_Date | L1: Expected_Collection_Date | M1: Scenario_Adjusted_Probability
A2: AR-260001 | B2: C00007 | C2: Ironstone Enterprises | D2: A | E2: 46154 | F2: {=_xlfn.IFS(G2="EM15",EOMONTH(E2,0)+15, G2="EM30",EOMONTH(E2,0)+30, G2="EM45",EOMONTH(E2,0)+45, G2="EM60",EOMONTH(E2,0)+60, G2="OA15",E2+15, G2="OA30",E2+30, G2="OA60",E2+60 )} -> 46203 | G2: EM30 | H2: 124000 | I2: =INDEX(Customer_list!$G$2:$G$21,MATCH(B2,Customer_list!$B$2:$B$21,0)) -> 0.97 | J2: Collected | K2: 46203 | L2: =IF(J2="Collected",K2,IF(J2="Open",F2,F2+INDEX(Customer_list!$H$2:$H$21,MATCH(B2,Customer_list!$B$2:$B$21,0))*Weekly_Cash_Flow_Summary!$B$8)) -> 46203 | M2: =MIN(1,MAX(0,I2+Weekly_Cash_Flow_Summary!$B$7)) -> 0.97
A3: AR-260002 | B3: C00009 | C3: Westfall Commercial Group | D3: A | E3: 46132 | F3: {=_xlfn.IFS(G3="EM15",EOMONTH(E3,0)+15, G3="EM30",EOMONTH(E3,0)+30, G3="EM45",EOMONTH(E3,0)+45, G3="EM60",EOMONTH(E3,0)+60, G3="OA15",E3+15, G3="OA30",E3+30, G3="OA60",E3+60 )} -> 46172 | G3: EM30 | H3: 305500 | I3: =INDEX(Customer_list!$G$2:$G$21,MATCH(B3,Customer_list!$B$2:$B$21,0)) -> 0.9 | J3: Collected | K3: 46178 | L3: =IF(J3="Collected",K3,IF(J3="Open",F3,F3+INDEX(Customer_list!$H$2:$H$21,MATCH(B3,Customer_list!$B$2:$B$21,0))*Weekly_Cash_Flow_Summary!$B$8)) -> 46178 | M3: =MIN(1,MAX(0,I3+Weekly_Cash_Flow_Summary!$B$7)) -> 0.9
A4: AR-260003 | B4: C00018 | C4: Lakeshore Retail Co. | D4: A | E4: 46163 | F4: {=_xlfn.IFS(G4="EM15",EOMONTH(E4,0)+15, G4="EM30",EOMONTH(E4,0)+30, G4="EM45",EOMONTH(E4,0)+45, G4="EM60",EOMONTH(E4,0)+60, G4="OA15",E4+15, G4="OA30",E4+30, G4="OA60",E4+60 )} -> 46193 | G4: OA30 | H4: 329000 | I4: =INDEX(Customer_list!$G$2:$G$21,MATCH(B4,Customer_list!$B$2:$B$21,0)) -> 0.97 | J4: Collected | K4: 46193 | L4: =IF(J4="Collected",K4,IF(J4="Open",F4,F4+INDEX(Customer_list!$H$2:$H$21,MATCH(B4,Customer_list!$B$2:$B$21,0))*Weekly_Cash_Flow_Summary!$B$8)) -> 46193 | M4: =MIN(1,MAX(0,I4+Weekly_Cash_Flow_Summary!$B$7)) -> 0.97
A5: AR-260004 | B5: C00009 | C5: Westfall Commercial Group | D5: A | E5: 46196 | F5: {=_xlfn.IFS(G5="EM15",EOMONTH(E5,0)+15, G5="EM30",EOMONTH(E5,0)+30, G5="EM45",EOMONTH(E5,0)+45, G5="EM60",EOMONTH(E5,0)+60, G5="OA15",E5+15, G5="OA30",E5+30, G5="OA60",E5+60 )} -> 46233 | G5: EM30 | H5: 103500 | I5: =INDEX(Customer_list!$G$2:$G$21,MATCH(B5,Customer_list!$B$2:$B$21,0)) -> 0.9 | J5: Open | L5: =IF(J5="Collected",K5,IF(J5="Open",F5,F5+INDEX(Customer_list!$H$2:$H$21,MATCH(B5,Customer_list!$B$2:$B$21,0))*Weekly_Cash_Flow_Summary!$B$8)) -> 46233 | M5: =MIN(1,MAX(0,I5+Weekly_Cash_Flow_Summary!$B$7)) -> 0.9
A6: AR-260005 | B6: C00011 | C6: Riverton Wholesale Ltd. | D6: B | E6: 46119 | F6: {=_xlfn.IFS(G6="EM15",EOMONTH(E6,0)+15, G6="EM30",EOMONTH(E6,0)+30, G6="EM45",EOMONTH(E6,0)+45, G6="EM60",EOMONTH(E6,0)+60, G6="OA15",E6+15, G6="OA30",E6+30, G6="OA60",E6+60 )} -> 46134 | G6: OA15 | H6: 165500 | I6: =INDEX(Customer_list!$G$2:$G$21,MATCH(B6,Customer_list!$B$2:$B$21,0)) -> 0.75 | J6: Collected | K6: 46162 | L6: =IF(J6="Collected",K6,IF(J6="Open",F6,F6+INDEX(Customer_list!$H$2:$H$21,MATCH(B6,Customer_list!$B$2:$B$21,0))*Weekly_Cash_Flow_Summary!$B$8)) -> 46162 | M6: =MIN(1,MAX(0,I6+Weekly_Cash_Flow_Summary!$B$7)) -> 0.75
A7: AR-260006 | B7: C00005 | C7: Crestwood Merchandise Inc. | D7: C | E7: 46122 | F7: {=_xlfn.IFS(G7="EM15",EOMONTH(E7,0)+15, G7="EM30",EOMONTH(E7,0)+30, G7="EM45",EOMONTH(E7,0)+45, G7="EM60",EOMONTH(E7,0)+60, G7="OA15",E7+15, G7="OA30",E7+30, G7="OA60",E7+60 )} -> 46152 | G7: OA30 | H7: 73500 | I7: =INDEX(Customer_list!$G$2:$G$21,MATCH(B7,Customer_list!$B$2:$B$21,0)) -> 0.75 | J7: Overdue | L7: =IF(J7="Collected",K7,IF(J7="Open",F7,F7+INDEX(Customer_list!$H$2:$H$21,MATCH(B7,Customer_list!$B$2:$B$21,0))*Weekly_Cash_Flow_Summary!$B$8)) -> 46177 | M7: =MIN(1,MAX(0,I7+Weekly_Cash_Flow_Summary!$B$7)) -> 0.75
A8: AR-260007 | B8: C00013 | C8: Pinehill Distribution Inc. | D8: B | E8: 46218 | F8: {=_xlfn.IFS(G8="EM15",EOMONTH(E8,0)+15, G8="EM30",EOMONTH(E8,0)+30, G8="EM45",EOMONTH(E8,0)+45, G8="EM60",EOMONTH(E8,0)+60, G8="OA15",E8+15, G8="OA30",E8+30, G8="OA60",E8+60 )} -> 46248 | G8: OA30 | H8: 208000 | I8: =INDEX(Customer_list!$G$2:$G$21,MATCH(B8,Customer_list!$B$2:$B$21,0)) -> 0.75 | J8: Open | L8: =IF(J8="Collected",K8,IF(J8="Open",F8,F8+INDEX(Customer_list!$H$2:$H$21,MATCH(B8,Customer_list!$B$2:$B$21,0))*Weekly_Cash_Flow_Summary!$B$8)) -> 46248 | M8: =MIN(1,MAX(0,I8+Weekly_Cash_Flow_Summary!$B$7)) -> 0.75
A9: AR-260008 | B9: C00009 | C9: Westfall Commercial Group | D9: A | E9: 46181 | F9: {=_xlfn.IFS(G9="EM15",EOMONTH(E9,0)+15, G9="EM30",EOMONTH(E9,0)+30, G9="EM45",EOMONTH(E9,0)+45, G9="EM60",EOMONTH(E9,0)+60, G9="OA15",E9+15, G9="OA30",E9+30, G9="OA60",E9+60 )} -> 46233 | G9: EM30 | H9: 336500 | I9: =INDEX(Customer_list!$G$2:$G$21,MATCH(B9,Customer_list!$B$2:$B$21,0)) -> 0.9 | J9: Open | L9: =IF(J9="Collected",K9,IF(J9="Open",F9,F9+INDEX(Customer_list!$H$2:$H$21,MATCH(B9,Customer_list!$B$2:$B$21,0))*Weekly_Cash_Flow_Summary!$B$8)) -> 46233 | M9: =MIN(1,MAX(0,I9+Weekly_Cash_Flow_Summary!$B$7)) -> 0.9
A10: AR-260009 | B10: C00020 | C10: Willowmere Commercial Ltd. | D10: C | E10: 46125 | F10: {=_xlfn.IFS(G10="EM15",EOMONTH(E10,0)+15, G10="EM30",EOMONTH(E10,0)+30, G10="EM45",EOMONTH(E10,0)+45, G10="EM60",EOMONTH(E10,0)+60, G10="OA15",E10+15, G10="OA30",E10+30, G10="OA60",E10+60 )} -> 46202 | G10: EM60 | H10: 261000 | I10: =INDEX(Customer_list!$G$2:$G$21,MATCH(B10,Customer_list!$B$2:$B$21,0)) -> 0.97 | J10: Collected | K10: 46208 | L10: =IF(J10="Collected",K10,IF(J10="Open",F10,F10+INDEX(Customer_list!$H$2:$H$21,MATCH(B10,Customer_list!$B$2:$B$21,0))*Weekly_Cash_Flow_Summary!$B$8)) -> 46208 | M10: =MIN(1,MAX(0,I10+Weekly_Cash_Flow_Summary!$B$7)) -> 0.97
A11: AR-260010 | B11: C00013 | C11: Pinehill Distribution Inc. | D11: B | E11: 46159 | F11: {=_xlfn.IFS(G11="EM15",EOMONTH(E11,0)+15, G11="EM30",EOMONTH(E11,0)+30, G11="EM45",EOMONTH(E11,0)+45, G11="EM60",EOMONTH(E11,0)+60, G11="OA15",E11+15, G11="OA30",E11+30, G11="OA60",E11+60 )} -> 46189 | G11: OA30 | H11: 301000 | I11: =INDEX(Customer_list!$G$2:$G$21,MATCH(B11,Customer_list!$B$2:$B$21,0)) -> 0.75 | J11: Overdue | L11: =IF(J11="Collected",K11,IF(J11="Open",F11,F11+INDEX(Customer_list!$H$2:$H$21,MATCH(B11,Customer_list!$B$2:$B$21,0))*Weekly_Cash_Flow_Summary!$B$8)) -> 46214 | M11: =MIN(1,MAX(0,I11+Weekly_Cash_Flow_Summary!$B$7)) -> 0.75
A12: AR-260011 | B12: C00008 | C12: Sunridge Retail Partners | D12: B | E12: 46187 | F12: {=_xlfn.IFS(G12="EM15",EOMONTH(E12,0)+15, G12="EM30",EOMONTH(E12,0)+30, G12="EM45",EOMONTH(E12,0)+45, G12="EM60",EOMONTH(E12,0)+60, G12="OA15",E12+15, G12="OA30",E12+30, G12="OA60",E12+60 )} -> 46217 | G12: OA30 | H12: 61500 | I12: =INDEX(Customer_list!$G$2:$G$21,MATCH(B12,Customer_list!$B$2:$B$21,0)) -> 0.9 | J12: Overdue | L12: =IF(J12="Collected",K12,IF(J12="Open",F12,F12+INDEX(Customer_list!$H$2:$H$21,MATCH(B12,Customer_list!$B$2:$B$21,0))*Weekly_Cash_Flow_Summary!$B$8)) -> 46227 | M12: =MIN(1,MAX(0,I12+Weekly_Cash_Flow_Summary!$B$7)) -> 0.9
A13: AR-260012 | B13: C00011 | C13: Riverton Wholesale Ltd. | D13: B | E13: 46120 | F13: {=_xlfn.IFS(G13="EM15",EOMONTH(E13,0)+15, G13="EM30",EOMONTH(E13,0)+30, G13="EM45",EOMONTH(E13,0)+45, G13="EM60",EOMONTH(E13,0)+60, G13="OA15",E13+15, G13="OA30",E13+30, G13="OA60",E13+60 )} -> 46135 | G13: OA15 | H13: 322500 | I13: =INDEX(Customer_list!$G$2:$G$21,MATCH(B13,Customer_list!$B$2:$B$21,0)) -> 0.75 | J13: Collected | K13: 46162 | L13: =IF(J13="Collected",K13,IF(J13="Open",F13,F13+INDEX(Customer_list!$H$2:$H$21,MATCH(B13,Customer_list!$B$2:$B$21,0))*Weekly_Cash_Flow_Summary!$B$8)) -> 46162 | M13: =MIN(1,MAX(0,I13+Weekly_Cash_Flow_Summary!$B$7)) -> 0.75
A14: AR-260013 | B14: C00011 | C14: Riverton Wholesale Ltd. | D14: B | E14: 46229 | F14: {=_xlfn.IFS(G14="EM15",EOMONTH(E14,0)+15, G14="EM30",EOMONTH(E14,0)+30, G14="EM45",EOMONTH(E14,0)+45, G14="EM60",EOMONTH(E14,0)+60, G14="OA15",E14+15, G14="OA30",E14+30, G14="OA60",E14+60 )} -> 46244 | G14: OA15 | H14: 44000 | I14: =INDEX(Customer_list!$G$2:$G$21,MATCH(B14,Customer_list!$B$2:$B$21,0)) -> 0.75 | J14: Open | L14: =IF(J14="Collected",K14,IF(J14="Open",F14,F14+INDEX(Customer_list!$H$2:$H$21,MATCH(B14,Customer_list!$B$2:$B$21,0))*Weekly_Cash_Flow_Summary!$B$8)) -> 46244 | M14: =MIN(1,MAX(0,I14+Weekly_Cash_Flow_Summary!$B$7)) -> 0.75
A15: AR-260014 | B15: C00002 | C15: Northgate Commerce Co. | D15: B | E15: 46177 | F15: {=_xlfn.IFS(G15="EM15",EOMONTH(E15,0)+15, G15="EM30",EOMONTH(E15,0)+30, G15="EM45",EOMONTH(E15,0)+45, G15="EM60",EOMONTH(E15,0)+60, G15="OA15",E15+15, G15="OA30",E15+30, G15="OA60",E15+60 )} -> 46237 | G15: OA60 | H15: 62000 | I15: =INDEX(Customer_list!$G$2:$G$21,MATCH(B15,Customer_list!$B$2:$B$21,0)) -> 0.9 | J15: Open | L15: =IF(J15="Collected",K15,IF(J15="Open",F15,F15+INDEX(Customer_list!$H$2:$H$21,MATCH(B15,Customer_list!$B$2:$B$21,0))*Weekly_Cash_Flow_Summary!$B$8)) -> 46237 | M15: =MIN(1,MAX(0,I15+Weekly_Cash_Flow_Summary!$B$7)) -> 0.9
A16: AR-260015 | B16: C00016 | C16: Fairview Merchants Ltd. | D16: B | E16: 46140 | F16: {=_xlfn.IFS(G16="EM15",EOMONTH(E16,0)+15, G16="EM30",EOMONTH(E16,0)+30, G16="EM45",EOMONTH(E16,0)+45, G16="EM60",EOMONTH(E16,0)+60, G16="OA15",E16+15, G16="OA30",E16+30, G16="OA60",E16+60 )} -> 46157 | G16: EM15 | H16: 219500 | I16: =INDEX(Customer_list!$G$2:$G$21,MATCH(B16,Customer_list!$B$2:$B$21,0)) -> 0.9 | J16: Collected | K16: 46167 | L16: =IF(J16="Collected",K16,IF(J16="Open",F16,F16+INDEX(Customer_list!$H$2:$H$21,MATCH(B16,Customer_list!$B$2:$B$21,0))*Weekly_Cash_Flow_Summary!$B$8)) -> 46167 | M16: =MIN(1,MAX(0,I16+Weekly_Cash_Flow_Summary!$B$7)) -> 0.9
A17: AR-260016 | B17: C00020 | C17: Willowmere Commercial Ltd. | D17: C | E17: 46117 | F17: {=_xlfn.IFS(G17="EM15",EOMONTH(E17,0)+15, G17="EM30",EOMONTH(E17,0)+30, G17="EM45",EOMONTH(E17,0)+45, G17="EM60",EOMONTH(E17,0)+60, G17="OA15",E17+15, G17="OA30",E17+30, G17="OA60",E17+60 )} -> 46202 | G17: EM60 | H17: 105500 | I17: =INDEX(Customer_list!$G$2:$G$21,MATCH(B17,Customer_list!$B$2:$B$21,0)) -> 0.97 | J17: Collected | K17: 46208 | L17: =IF(J17="Collected",K17,IF(J17="Open",F17,F17+INDEX(Customer_list!$H$2:$H$21,MATCH(B17,Customer_list!$B$2:$B$21,0))*Weekly_Cash_Flow_Summary!$B$8)) -> 46208 | M17: =MIN(1,MAX(0,I17+Weekly_Cash_Flow_Summary!$B$7)) -> 0.97
A18: AR-260017 | B18: C00003 | C18: BluePeak Distributors | D18: A | E18: 46124 | F18: {=_xlfn.IFS(G18="EM15",EOMONTH(E18,0)+15, G18="EM30",EOMONTH(E18,0)+30, G18="EM45",EOMONTH(E18,0)+45, G18="EM60",EOMONTH(E18,0)+60, G18="OA15",E18+15, G18="OA30",E18+30, G18="OA60",E18+60 )} -> 46202 | G18: EM60 | H18: 160000 | I18: =INDEX(Customer_list!$G$2:$G$21,MATCH(B18,Customer_list!$B$2:$B$21,0)) -> 0.97 | J18: Collected | K18: 46203 | L18: =IF(J18="Collected",K18,IF(J18="Open",F18,F18+INDEX(Customer_list!$H$2:$H$21,MATCH(B18,Customer_list!$B$2:$B$21,0))*Weekly_Cash_Flow_Summary!$B$8)) -> 46203 | M18: =MIN(1,MAX(0,I18+Weekly_Cash_Flow_Summary!$B$7)) -> 0.97
A19: AR-260018 | B19: C00002 | C19: Northgate Commerce Co. | D19: B | E19: 46168 | F19: {=_xlfn.IFS(G19="EM15",EOMONTH(E19,0)+15, G19="EM30",EOMONTH(E19,0)+30, G19="EM45",EOMONTH(E19,0)+45, G19="EM60",EOMONTH(E19,0)+60, G19="OA15",E19+15, G19="OA30",E19+30, G19="OA60",E19+60 )} -> 46228 | G19: OA60 | H19: 339500 | I19: =INDEX(Customer_list!$G$2:$G$21,MATCH(B19,Customer_list!$B$2:$B$21,0)) -> 0.9 | J19: Overdue | L19: =IF(J19="Collected",K19,IF(J19="Open",F19,F19+INDEX(Customer_list!$H$2:$H$21,MATCH(B19,Customer_list!$B$2:$B$21,0))*Weekly_Cash_Flow_Summary!$B$8)) -> 46238 | M19: =MIN(1,MAX(0,I19+Weekly_Cash_Flow_Summary!$B$7)) -> 0.9
A20: AR-260019 | B20: C00010 | C20: Oakhaven Trading Co. | D20: A | E20: 46166 | F20: {=_xlfn.IFS(G20="EM15",EOMONTH(E20,0)+15, G20="EM30",EOMONTH(E20,0)+30, G20="EM45",EOMONTH(E20,0)+45, G20="EM60",EOMONTH(E20,0)+60, G20="OA15",E20+15, G20="OA30",E20+30, G20="OA60",E20+60 )} -> 46196 | G20: OA30 | H20: 109500 | I20: =INDEX(Customer_list!$G$2:$G$21,MATCH(B20,Customer_list!$B$2:$B$21,0)) -> 0.97 | J20: Collected | K20: 46203 | L20: =IF(J20="Collected",K20,IF(J20="Open",F20,F20+INDEX(Customer_list!$H$2:$H$21,MATCH(B20,Customer_list!$B$2:$B$21,0))*Weekly_Cash_Flow_Summary!$B$8)) -> 46203 | M20: =MIN(1,MAX(0,I20+Weekly_Cash_Flow_Summary!$B$7)) -> 0.97
A21: AR-260020 | B21: C00012 | C21: Goldenbridge Retailers | D21: B | E21: 46121 | F21: {=_xlfn.IFS(G21="EM15",EOMONTH(E21,0)+15, G21="EM30",EOMONTH(E21,0)+30, G21="EM45",EOMONTH(E21,0)+45, G21="EM60",EOMONTH(E21,0)+60, G21="OA15",E21+15, G21="OA30",E21+30, G21="OA60",E21+60 )} -> 46151 | G21: OA30 | H21: 105500 | I21: =INDEX(Customer_list!$G$2:$G$21,MATCH(B21,Customer_list!$B$2:$B$21,0)) -> 0.9 | J21: Collected | K21: 46167 | L21: =IF(J21="Collected",K21,IF(J21="Open",F21,F21+INDEX(Customer_list!$H$2:$H$21,MATCH(B21,Customer_list!$B$2:$B$21,0))*Weekly_Cash_Flow_Summary!$B$8)) -> 46167 | M21: =MIN(1,MAX(0,I21+Weekly_Cash_Flow_Summary!$B$7)) -> 0.9
A22: AR-260021 | B22: C00018 | C22: Lakeshore Retail Co. | D22: A | E22: 46143 | F22: {=_xlfn.IFS(G22="EM15",EOMONTH(E22,0)+15, G22="EM30",EOMONTH(E22,0)+30, G22="EM45",EOMONTH(E22,0)+45, G22="EM60",EOMONTH(E22,0)+60, G22="OA15",E22+15, G22="OA30",E22+30, G22="OA60",E22+60 )} -> 46173 | G22: OA30 | H22: 262500 | I22: =INDEX(Customer_list!$G$2:$G$21,MATCH(B22,Customer_list!$B$2:$B$21,0)) -> 0.97 | J22: Collected | K22: 46178 | L22: =IF(J22="Collected",K22,IF(J22="Open",F22,F22+INDEX(Customer_list!$H$2:$H$21,MATCH(B22,Customer_list!$B$2:$B$21,0))*Weekly_Cash_Flow_Summary!$B$8)) -> 46178 | M22: =MIN(1,MAX(0,I22+Weekly_Cash_Flow_Summary!$B$7)) -> 0.97
A23: AR-260022 | B23: C00017 | C23: Cedarpoint Trading Inc. | D23: C | E23: 46124 | F23: {=_xlfn.IFS(G23="EM15",EOMONTH(E23,0)+15, G23="EM30",EOMONTH(E23,0)+30, G23="EM45",EOMONTH(E23,0)+45, G23="EM60",EOMONTH(E23,0)+60, G23="OA15",E23+15, G23="OA30",E23+30, G23="OA60",E23+60 )} -> 46187 | G23: EM45 | H23: 135000 | I23: =INDEX(Customer_list!$G$2:$G$21,MATCH(B23,Customer_list!$B$2:$B$21,0)) -> 0.75 | J23: Overdue | L23: =IF(J23="Collected",K23,IF(J23="Open",F23,F23+INDEX(Customer_list!$H$2:$H$21,MATCH(B23,Customer_list!$B$2:$B$21,0))*Weekly_Cash_Flow_Summary!$B$8)) -> 46212 | M23: =MIN(1,MAX(0,I23+Weekly_Cash_Flow_Summary!$B$7)) -> 0.75
A24: AR-260023 | B24: C00004 | C24: Harborview Trading Ltd. | D24: B | E24: 46183 | F24: {=_xlfn.IFS(G24="EM15",EOMONTH(E24,0)+15, G24="EM30",EOMONTH(E24,0)+30, G24="EM45",EOMONTH(E24,0)+45, G24="EM60",EOMONTH(E24,0)+60, G24="OA15",E24+15, G24="OA30",E24+30, G24="OA60",E24+60 )} -> 46263 | G24: EM60 | H24: 190000 | I24: =INDEX(Customer_list!$G$2:$G$21,MATCH(B24,Customer_list!$B$2:$B$21,0)) -> 0.9 | J24: Open | L24: =IF(J24="Collected",K24,IF(J24="Open",F24,F24+INDEX(Customer_list!$H$2:$H$21,MATCH(B24,Customer_list!$B$2:$B$21,0))*Weekly_Cash_Flow_Summary!$B$8)) -> 46263 | M24: =MIN(1,MAX(0,I24+Weekly_Cash_Flow_Summary!$B$7)) -> 0.9
A25: AR-260024 | B25: C00017 | C25: Cedarpoint Trading Inc. | D25: C | E25: 46167 | F25: {=_xlfn.IFS(G25="EM15",EOMONTH(E25,0)+15, G25="EM30",EOMONTH(E25,0)+30, G25="EM45",EOMONTH(E25,0)+45, G25="EM60",EOMONTH(E25,0)+60, G25="OA15",E25+15, G25="OA30",E25+30, G25="OA60",E25+60 )} -> 46218 | G25: EM45 | H25: 140000 | I25: =INDEX(Customer_list!$G$2:$G$21,MATCH(B25,Customer_list!$B$2:$B$21,0)) -> 0.75 | J25: Overdue | L25: =IF(J25="Collected",K25,IF(J25="Open",F25,F25+INDEX(Customer_list!$H$2:$H$21,MATCH(B25,Customer_list!$B$2:$B$21,0))*Weekly_Cash_Flow_Summary!$B$8)) -> 46243 | M25: =MIN(1,MAX(0,I25+Weekly_Cash_Flow_Summary!$B$7)) -> 0.75
A26: AR-260025 | B26: C00014 | C26: Clearwater Commerce Co. | D26: A | E26: 46120 | F26: {=_xlfn.IFS(G26="EM15",EOMONTH(E26,0)+15, G26="EM30",EOMONTH(E26,0)+30, G26="EM45",EOMONTH(E26,0)+45, G26="EM60",EOMONTH(E26,0)+60, G26="OA15",E26+15, G26="OA30",E26+30, G26="OA60",E26+60 )} -> 46187 | G26: EM45 | H26: 185500 | I26: =INDEX(Customer_list!$G$2:$G$21,MATCH(B26,Customer_list!$B$2:$B$21,0)) -> 0.97 | J26: Collected | K26: 46188 | L26: =IF(J26="Collected",K26,IF(J26="Open",F26,F26+INDEX(Customer_list!$H$2:$H$21,MATCH(B26,Customer_list!$B$2:$B$21,0))*Weekly_Cash_Flow_Summary!$B$8)) -> 46188 | M26: =MIN(1,MAX(0,I26+Weekly_Cash_Flow_Summary!$B$7)) -> 0.97
A27: AR-260026 | B27: C00006 | C27: Meadowbrook Supply Co. | D27: B | E27: 46218 | F27: {=_xlfn.IFS(G27="EM15",EOMONTH(E27,0)+15, G27="EM30",EOMONTH(E27,0)+30, G27="EM45",EOMONTH(E27,0)+45, G27="EM60",EOMONTH(E27,0)+60, G27="OA15",E27+15, G27="OA30",E27+30, G27="OA60",E27+60 )} -> 46294 | G27: EM60 | H27: 130500 | I27: =INDEX(Customer_list!$G$2:$G$21,MATCH(B27,Customer_list!$B$2:$B$21,0)) -> 0.9 | J27: Open | L27: =IF(J27="Collected",K27,IF(J27="Open",F27,F27+INDEX(Customer_list!$H$2:$H$21,MATCH(B27,Customer_list!$B$2:$B$21,0))*Weekly_Cash_Flow_Summary!$B$8)) -> 46294 | M27: =MIN(1,MAX(0,I27+Weekly_Cash_Flow_Summary!$B$7)) -> 0.9
A28: AR-260027 | B28: C00008 | C28: Sunridge Retail Partners | D28: B | E28: 46185 | F28: {=_xlfn.IFS(G28="EM15",EOMONTH(E28,0)+15, G28="EM30",EOMONTH(E28,0)+30, G28="EM45",EOMONTH(E28,0)+45, G28="EM60",EOMONTH(E28,0)+60, G28="OA15",E28+15, G28="OA30",E28+30, G28="OA60",E28+60 )} -> 46215 | G28: OA30 | H28: 317500 | I28: =INDEX(Customer_list!$G$2:$G$21,MATCH(B28,Customer_list!$B$2:$B$21,0)) -> 0.9 | J28: Overdue | L28: =IF(J28="Collected",K28,IF(J28="Open",F28,F28+INDEX(Customer_list!$H$2:$H$21,MATCH(B28,Customer_list!$B$2:$B$21,0))*Weekly_Cash_Flow_Summary!$B$8)) -> 46225 | M28: =MIN(1,MAX(0,I28+Weekly_Cash_Flow_Summary!$B$7)) -> 0.9
A29: AR-260028 | B29: C00018 | C29: Lakeshore Retail Co. | D29: A | E29: 46128 | F29: {=_xlfn.IFS(G29="EM15",EOMONTH(E29,0)+15, G29="EM30",EOMONTH(E29,0)+30, G29="EM45",EOMONTH(E29,0)+45, G29="EM60",EOMONTH(E29,0)+60, G29="OA15",E29+15, G29="OA30",E29+30, G29="OA60",E29+60 )} -> 46158 | G29: OA30 | H29: 131500 | I29: =INDEX(Customer_list!$G$2:$G$21,MATCH(B29,Customer_list!$B$2:$B$21,0)) -> 0.97 | J29: Collected | K29: 46162 | L29: =IF(J29="Collected",K29,IF(J29="Open",F29,F29+INDEX(Customer_list!$H$2:$H$21,MATCH(B29,Customer_list!$B$2:$B$21,0))*Weekly_Cash_Flow_Summary!$B$8)) -> 46162 | M29: =MIN(1,MAX(0,I29+Weekly_Cash_Flow_Summary!$B$7)) -> 0.97
A30: AR-260029 | B30: C00006 | C30: Meadowbrook Supply Co. | D30: B | E30: 46141 | F30: {=_xlfn.IFS(G30="EM15",EOMONTH(E30,0)+15, G30="EM30",EOMONTH(E30,0)+30, G30="EM45",EOMONTH(E30,0)+45, G30="EM60",EOMONTH(E30,0)+60, G30="OA15",E30+15, G30="OA30",E30+30, G30="OA60",E30+60 )} -> 46202 | G30: EM60 | H30: 281500 | I30: =INDEX(Customer_list!$G$2:$G$21,MATCH(B30,Customer_list!$B$2:$B$21,0)) -> 0.9 | J30: Collected | K30: 46208 | L30: =IF(J30="Collected",K30,IF(J30="Open",F30,F30+INDEX(Customer_list!$H$2:$H$21,MATCH(B30,Customer_list!$B$2:$B$21,0))*Weekly_Cash_Flow_Summary!$B$8)) -> 46208 | M30: =MIN(1,MAX(0,I30+Weekly_Cash_Flow_Summary!$B$7)) -> 0.9
A31: AR-260030 | B31: C00001 | C31: Silverline Retail Group | D31: C | E31: 46193 | F31: {=_xlfn.IFS(G31="EM15",EOMONTH(E31,0)+15, G31="EM30",EOMONTH(E31,0)+30, G31="EM45",EOMONTH(E31,0)+45, G31="EM60",EOMONTH(E31,0)+60, G31="OA15",E31+15, G31="OA30",E31+30, G31="OA60",E31+60 )} -> 46218 | G31: EM15 | H31: 95000 | I31: =INDEX(Customer_list!$G$2:$G$21,MATCH(B31,Customer_list!$B$2:$B$21,0)) -> 0.97 | J31: Collected | K31: 46218 | L31: =IF(J31="Collected",K31,IF(J31="Open",F31,F31+INDEX(Customer_list!$H$2:$H$21,MATCH(B31,Customer_list!$B$2:$B$21,0))*Weekly_Cash_Flow_Summary!$B$8)) -> 46218 | M31: =MIN(1,MAX(0,I31+Weekly_Cash_Flow_Summary!$B$7)) -> 0.97
A32: AR-260031 | B32: C00007 | C32: Ironstone Enterprises | D32: A | E32: 46193 | F32: {=_xlfn.IFS(G32="EM15",EOMONTH(E32,0)+15, G32="EM30",EOMONTH(E32,0)+30, G32="EM45",EOMONTH(E32,0)+45, G32="EM60",EOMONTH(E32,0)+60, G32="OA15",E32+15, G32="OA30",E32+30, G32="OA60",E32+60 )} -> 46233 | G32: EM30 | H32: 314500 | I32: =INDEX(Customer_list!$G$2:$G$21,MATCH(B32,Customer_list!$B$2:$B$21,0)) -> 0.97 | J32: Open | L32: =IF(J32="Collected",K32,IF(J32="Open",F32,F32+INDEX(Customer_list!$H$2:$H$21,MATCH(B32,Customer_list!$B$2:$B$21,0))*Weekly_Cash_Flow_Summary!$B$8)) -> 46233 | M32: =MIN(1,MAX(0,I32+Weekly_Cash_Flow_Summary!$B$7)) -> 0.97
A33: AR-260032 | B33: C00016 | C33: Fairview Merchants Ltd. | D33: B | E33: 46187 | F33: {=_xlfn.IFS(G33="EM15",EOMONTH(E33,0)+15, G33="EM30",EOMONTH(E33,0)+30, G33="EM45",EOMONTH(E33,0)+45, G33="EM60",EOMONTH(E33,0)+60, G33="OA15",E33+15, G33="OA30",E33+30, G33="OA60",E33+60 )} -> 46218 | G33: EM15 | H33: 302500 | I33: =INDEX(Customer_list!$G$2:$G$21,MATCH(B33,Customer_list!$B$2:$B$21,0)) -> 0.9 | J33: Collected | K33: 46228 | L33: =IF(J33="Collected",K33,IF(J33="Open",F33,F33+INDEX(Customer_list!$H$2:$H$21,MATCH(B33,Customer_list!$B$2:$B$21,0))*Weekly_Cash_Flow_Summary!$B$8)) -> 46228 | M33: =MIN(1,MAX(0,I33+Weekly_Cash_Flow_Summary!$B$7)) -> 0.9
A34: AR-260033 | B34: C00010 | C34: Oakhaven Trading Co. | D34: A | E34: 46120 | F34: {=_xlfn.IFS(G34="EM15",EOMONTH(E34,0)+15, G34="EM30",EOMONTH(E34,0)+30, G34="EM45",EOMONTH(E34,0)+45, G34="EM60",EOMONTH(E34,0)+60, G34="OA15",E34+15, G34="OA30",E34+30, G34="OA60",E34+60 )} -> 46150 | G34: OA30 | H34: 326000 | I34: =INDEX(Customer_list!$G$2:$G$21,MATCH(B34,Customer_list!$B$2:$B$21,0)) -> 0.97 | J34: Collected | K34: 46157 | L34: =IF(J34="Collected",K34,IF(J34="Open",F34,F34+INDEX(Customer_list!$H$2:$H$21,MATCH(B34,Customer_list!$B$2:$B$21,0))*Weekly_Cash_Flow_Summary!$B$8)) -> 46157 | M34: =MIN(1,MAX(0,I34+Weekly_Cash_Flow_Summary!$B$7)) -> 0.97
A35: AR-260034 | B35: C00006 | C35: Meadowbrook Supply Co. | D35: B | E35: 46186 | F35: {=_xlfn.IFS(G35="EM15",EOMONTH(E35,0)+15, G35="EM30",EOMONTH(E35,0)+30, G35="EM45",EOMONTH(E35,0)+45, G35="EM60",EOMONTH(E35,0)+60, G35="OA15",E35+15, G35="OA30",E35+30, G35="OA60",E35+60 )} -> 46263 | G35: EM60 | H35: 92500 | I35: =INDEX(Customer_list!$G$2:$G$21,MATCH(B35,Customer_list!$B$2:$B$21,0)) -> 0.9 | J35: Open | L35: =IF(J35="Collected",K35,IF(J35="Open",F35,F35+INDEX(Customer_list!$H$2:$H$21,MATCH(B35,Customer_list!$B$2:$B$21,0))*Weekly_Cash_Flow_Summary!$B$8)) -> 46263 | M35: =MIN(1,MAX(0,I35+Weekly_Cash_Flow_Summary!$B$7)) -> 0.9
A36: AR-260035 | B36: C00009 | C36: Westfall Commercial Group | D36: A | E36: 46187 | F36: {=_xlfn.IFS(G36="EM15",EOMONTH(E36,0)+15, G36="EM30",EOMONTH(E36,0)+30, G36="EM45",EOMONTH(E36,0)+45, G36="EM60",EOMONTH(E36,0)+60, G36="OA15",E36+15, G36="OA30",E36+30, G36="OA60",E36+60 )} -> 46233 | G36: EM30 | H36: 44500 | I36: =INDEX(Customer_list!$G$2:$G$21,MATCH(B36,Customer_list!$B$2:$B$21,0)) -> 0.9 | J36: Open | L36: =IF(J36="Collected",K36,IF(J36="Open",F36,F36+INDEX(Customer_list!$H$2:$H$21,MATCH(B36,Customer_list!$B$2:$B$21,0))*Weekly_Cash_Flow_Summary!$B$8)) -> 46233 | M36: =MIN(1,MAX(0,I36+Weekly_Cash_Flow_Summary!$B$7)) -> 0.9
A37: AR-260036 | B37: C00005 | C37: Crestwood Merchandise Inc. | D37: C | E37: 46163 | F37: {=_xlfn.IFS(G37="EM15",EOMONTH(E37,0)+15, G37="EM30",EOMONTH(E37,0)+30, G37="EM45",EOMONTH(E37,0)+45, G37="EM60",EOMONTH(E37,0)+60, G37="OA15",E37+15, G37="OA30",E37+30, G37="OA60",E37+60 )} -> 46193 | G37: OA30 | H37: 349000 | I37: =INDEX(Customer_list!$G$2:$G$21,MATCH(B37,Customer_list!$B$2:$B$21,0)) -> 0.75 | J37: Collected | K37: 46213 | L37: =IF(J37="Collected",K37,IF(J37="Open",F37,F37+INDEX(Customer_list!$H$2:$H$21,MATCH(B37,Customer_list!$B$2:$B$21,0))*Weekly_Cash_Flow_Summary!$B$8)) -> 46213 | M37: =MIN(1,MAX(0,I37+Weekly_Cash_Flow_Summary!$B$7)) -> 0.75
A38: AR-260037 | B38: C00016 | C38: Fairview Merchants Ltd. | D38: B | E38: 46119 | F38: {=_xlfn.IFS(G38="EM15",EOMONTH(E38,0)+15, G38="EM30",EOMONTH(E38,0)+30, G38="EM45",EOMONTH(E38,0)+45, G38="EM60",EOMONTH(E38,0)+60, G38="OA15",E38+15, G38="OA30",E38+30, G38="OA60",E38+60 )} -> 46157 | G38: EM15 | H38: 332500 | I38: =INDEX(Customer_list!$G$2:$G$21,MATCH(B38,Customer_list!$B$2:$B$21,0)) -> 0.9 | J38: Collected | K38: 46167 | L38: =IF(J38="Collected",K38,IF(J38="Open",F38,F38+INDEX(Customer_list!$H$2:$H$21,MATCH(B38,Customer_list!$B$2:$B$21,0))*Weekly_Cash_Flow_Summary!$B$8)) -> 46167 | M38: =MIN(1,MAX(0,I38+Weekly_Cash_Flow_Summary!$B$7)) -> 0.9
A39: AR-260038 | B39: C00018 | C39: Lakeshore Retail Co. | D39: A | E39: 46141 | F39: {=_xlfn.IFS(G39="EM15",EOMONTH(E39,0)+15, G39="EM30",EOMONTH(E39,0)+30, G39="EM45",EOMONTH(E39,0)+45, G39="EM60",EOMONTH(E39,0)+60, G39="OA15",E39+15, G39="OA30",E39+30, G39="OA60",E39+60 )} -> 46171 | G39: OA30 | H39: 332500 | I39: =INDEX(Customer_list!$G$2:$G$21,MATCH(B39,Customer_list!$B$2:$B$21,0)) -> 0.97 | J39: Collected | K39: 46178 | L39: =IF(J39="Collected",K39,IF(J39="Open",F39,F39+INDEX(Customer_list!$H$2:$H$21,MATCH(B39,Customer_list!$B$2:$B$21,0))*Weekly_Cash_Flow_Summary!$B$8)) -> 46178 | M39: =MIN(1,MAX(0,I39+Weekly_Cash_Flow_Summary!$B$7)) -> 0.97
A40: AR-260039 | B40: C00014 | C40: Clearwater Commerce Co. | D40: A | E40: 46118 | F40: {=_xlfn.IFS(G40="EM15",EOMONTH(E40,0)+15, G40="EM30",EOMONTH(E40,0)+30, G40="EM45",EOMONTH(E40,0)+45, G40="EM60",EOMONTH(E40,0)+60, G40="OA15",E40+15, G40="OA30",E40+30, G40="OA60",E40+60 )} -> 46187 | G40: EM45 | H40: 297500 | I40: =INDEX(Customer_list!$G$2:$G$21,MATCH(B40,Customer_list!$B$2:$B$21,0)) -> 0.97 | J40: Collected | K40: 46188 | L40: =IF(J40="Collected",K40,IF(J40="Open",F40,F40+INDEX(Customer_list!$H$2:$H$21,MATCH(B40,Customer_list!$B$2:$B$21,0))*Weekly_Cash_Flow_Summary!$B$8)) -> 46188 | M40: =MIN(1,MAX(0,I40+Weekly_Cash_Flow_Summary!$B$7)) -> 0.97
...

Sheet AP_detail
A1: Bill_ID | B1: Vendor_Code | C1: Vendor_Name | D1: Department | E1: Bill_Date | F1: Due_Date | G1: Payment_Terms | H1: Amount | I1: Priority | J1: Status | K1: Actual_Payment_Date | L1: Expected_Payment_Date
A2: AP-260001 | B2: =VLOOKUP(C2,Vendor_list!A:D,2,0) -> V00002 | C2: Coastal Line Logistics | D2: =VLOOKUP(C2,Vendor_list!A:D,4,0) -> C | E2: 46124 | F2: {=_xlfn.IFS(G2="EM15",EOMONTH(E2,0)+15, G2="EM30",EOMONTH(E2,0)+30, G2="EM45",EOMONTH(E2,0)+45, G2="EM60",EOMONTH(E2,0)+60, G2="EM90",EOMONTH(E2,0)+90, G2="OA15",E2+15, G2="OA30",E2+30, G2="OA60",E2+60)} -> 46232 | G2: =VLOOKUP(C2,Vendor_list!A:D,3,0) -> EM90 | H2: 223500 | I2: High | J2: Overdue | L2: =IF(J2="Paid",K2,IF(J2="Open",F2,F2+INDEX(Vendor_list!$F$2:$F$16,MATCH(B2,Vendor_list!$B$2:$B$16,0))*Weekly_Cash_Flow_Summary!$B$9)) -> 46234
A3: AP-260002 | B3: =VLOOKUP(C3,Vendor_list!A:D,2,0) -> V00011 | C3: Highcastle Equipment Co. | D3: =VLOOKUP(C3,Vendor_list!A:D,4,0) -> C | E3: 46138 | F3: {=_xlfn.IFS(G3="EM15",EOMONTH(E3,0)+15, G3="EM30",EOMONTH(E3,0)+30, G3="EM45",EOMONTH(E3,0)+45, G3="EM60",EOMONTH(E3,0)+60, G3="EM90",EOMONTH(E3,0)+90, G3="OA15",E3+15, G3="OA30",E3+30, G3="OA60",E3+60)} -> 46232 | G3: =VLOOKUP(C3,Vendor_list!A:D,3,0) -> EM90 | H3: 189500 | I3: High | J3: Overdue | L3: =IF(J3="Paid",K3,IF(J3="Open",F3,F3+INDEX(Vendor_list!$F$2:$F$16,MATCH(B3,Vendor_list!$B$2:$B$16,0))*Weekly_Cash_Flow_Summary!$B$9)) -> 46234
A4: AP-260003 | B4: =VLOOKUP(C4,Vendor_list!A:D,2,0) -> V00003 | C4: Amberfield Textiles | D4: =VLOOKUP(C4,Vendor_list!A:D,4,0) -> C | E4: 46132 | F4: {=_xlfn.IFS(G4="EM15",EOMONTH(E4,0)+15, G4="EM30",EOMONTH(E4,0)+30, G4="EM45",EOMONTH(E4,0)+45, G4="EM60",EOMONTH(E4,0)+60, G4="EM90",EOMONTH(E4,0)+90, G4="OA15",E4+15, G4="OA30",E4+30, G4="OA60",E4+60)} -> 46162 | G4: =VLOOKUP(C4,Vendor_list!A:D,3,0) -> OA30 | H4: 22500 | I4: Medium | J4: Paid | K4: 46167 | L4: =IF(J4="Paid",K4,IF(J4="Open",F4,F4+INDEX(Vendor_list!$F$2:$F$16,MATCH(B4,Vendor_list!$B$2:$B$16,0))*Weekly_Cash_Flow_Summary!$B$9)) -> 46167
A5: AP-260004 | B5: =VLOOKUP(C5,Vendor_list!A:D,2,0) -> V00007 | C5: Northline Freight Services | D5: =VLOOKUP(C5,Vendor_list!A:D,4,0) -> A | E5: 46207 | F5: {=_xlfn.IFS(G5="EM15",EOMONTH(E5,0)+15, G5="EM30",EOMONTH(E5,0)+30, G5="EM45",EOMONTH(E5,0)+45, G5="EM60",EOMONTH(E5,0)+60, G5="EM90",EOMONTH(E5,0)+90, G5="OA15",E5+15, G5="OA30",E5+30, G5="OA60",E5+60)} -> 46222 | G5: =VLOOKUP(C5,Vendor_list!A:D,3,0) -> OA15 | H5: 19000 | I5: High | J5: Paid | K5: 46228 | L5: =IF(J5="Paid",K5,IF(J5="Open",F5,F5+INDEX(Vendor_list!$F$2:$F$16,MATCH(B5,Vendor_list!$B$2:$B$16,0))*Weekly_Cash_Flow_Summary!$B$9)) -> 46228
A6: AP-260005 | B6: =VLOOKUP(C6,Vendor_list!A:D,2,0) -> V00003 | C6: Amberfield Textiles | D6: =VLOOKUP(C6,Vendor_list!A:D,4,0) -> C | E6: 46151 | F6: {=_xlfn.IFS(G6="EM15",EOMONTH(E6,0)+15, G6="EM30",EOMONTH(E6,0)+30, G6="EM45",EOMONTH(E6,0)+45, G6="EM60",EOMONTH(E6,0)+60, G6="EM90",EOMONTH(E6,0)+90, G6="OA15",E6+15, G6="OA30",E6+30, G6="OA60",E6+60)} -> 46181 | G6: =VLOOKUP(C6,Vendor_list!A:D,3,0) -> OA30 | H6: 258500 | I6: Medium | J6: Paid | K6: 46198 | L6: =IF(J6="Paid",K6,IF(J6="Open",F6,F6+INDEX(Vendor_list!$F$2:$F$16,MATCH(B6,Vendor_list!$B$2:$B$16,0))*Weekly_Cash_Flow_Summary!$B$9)) -> 46198
A7: AP-260006 | B7: =VLOOKUP(C7,Vendor_list!A:D,2,0) -> V00012 | C7: Starling Print & Packaging | D7: =VLOOKUP(C7,Vendor_list!A:D,4,0) -> B | E7: 46220 | F7: {=_xlfn.IFS(G7="EM15",EOMONTH(E7,0)+15, G7="EM30",EOMONTH(E7,0)+30, G7="EM45",EOMONTH(E7,0)+45, G7="EM60",EOMONTH(E7,0)+60, G7="EM90",EOMONTH(E7,0)+90, G7="OA15",E7+15, G7="OA30",E7+30, G7="OA60",E7+60)} -> 46235 | G7: =VLOOKUP(C7,Vendor_list!A:D,3,0) -> OA15 | H7: 79000 | I7: Low | J7: Open | L7: =IF(J7="Paid",K7,IF(J7="Open",F7,F7+INDEX(Vendor_list!$F$2:$F$16,MATCH(B7,Vendor_list!$B$2:$B$16,0))*Weekly_Cash_Flow_Summary!$B$9)) -> 46235
A8: AP-260007 | B8: =VLOOKUP(C8,Vendor_list!A:D,2,0) -> V00014 | C8: Kestrel Logistics Group | D8: =VLOOKUP(C8,Vendor_list!A:D,4,0) -> C | E8: 46123 | F8: {=_xlfn.IFS(G8="EM15",EOMONTH(E8,0)+15, G8="EM30",EOMONTH(E8,0)+30, G8="EM45",EOMONTH(E8,0)+45, G8="EM60",EOMONTH(E8,0)+60, G8="EM90",EOMONTH(E8,0)+90, G8="OA15",E8+15, G8="OA30",E8+30, G8="OA60",E8+60)} -> 46138 | G8: =VLOOKUP(C8,Vendor_list!A:D,3,0) -> OA15 | H8: 88500 | I8: Low | J8: Paid | K8: 46167 | L8: =IF(J8="Paid",K8,IF(J8="Open",F8,F8+INDEX(Vendor_list!$F$2:$F$16,MATCH(B8,Vendor_list!$B$2:$B$16,0))*Weekly_Cash_Flow_Summary!$B$9)) -> 46167
A9: AP-260008 | B9: =VLOOKUP(C9,Vendor_list!A:D,2,0) -> V00011 | C9: Highcastle Equipment Co. | D9: =VLOOKUP(C9,Vendor_list!A:D,4,0) -> C | E9: 46208 | F9: {=_xlfn.IFS(G9="EM15",EOMONTH(E9,0)+15, G9="EM30",EOMONTH(E9,0)+30, G9="EM45",EOMONTH(E9,0)+45, G9="EM60",EOMONTH(E9,0)+60, G9="EM90",EOMONTH(E9,0)+90, G9="OA15",E9+15, G9="OA30",E9+30, G9="OA60",E9+60)} -> 46324 | G9: =VLOOKUP(C9,Vendor_list!A:D,3,0) -> EM90 | H9: 246500 | I9: High | J9: Open | L9: =IF(J9="Paid",K9,IF(J9="Open",F9,F9+INDEX(Vendor_list!$F$2:$F$16,MATCH(B9,Vendor_list!$B$2:$B$16,0))*Weekly_Cash_Flow_Summary!$B$9)) -> 46324
A10: AP-260009 | B10: =VLOOKUP(C10,Vendor_list!A:D,2,0) -> V00003 | C10: Amberfield Textiles | D10: =VLOOKUP(C10,Vendor_list!A:D,4,0) -> C | E10: 46136 | F10: {=_xlfn.IFS(G10="EM15",EOMONTH(E10,0)+15, G10="EM30",EOMONTH(E10,0)+30, G10="EM45",EOMONTH(E10,0)+45, G10="EM60",EOMONTH(E10,0)+60, G10="EM90",EOMONTH(E10,0)+90, G10="OA15",E10+15, G10="OA30",E10+30, G10="OA60",E10+60)} -> 46166 | G10: =VLOOKUP(C10,Vendor_list!A:D,3,0) -> OA30 | H10: 230000 | I10: Medium | J10: Paid | K10: 46183 | L10: =IF(J10="Paid",K10,IF(J10="Open",F10,F10+INDEX(Vendor_list!$F$2:$F$16,MATCH(B10,Vendor_list!$B$2:$B$16,0))*Weekly_Cash_Flow_Summary!$B$9)) -> 46183
A11: AP-260010 | B11: =VLOOKUP(C11,Vendor_list!A:D,2,0) -> V00001 | C11: Granite Peak Manufacturing | D11: =VLOOKUP(C11,Vendor_list!A:D,4,0) -> A | E11: 46151 | F11: {=_xlfn.IFS(G11="EM15",EOMONTH(E11,0)+15, G11="EM30",EOMONTH(E11,0)+30, G11="EM45",EOMONTH(E11,0)+45, G11="EM60",EOMONTH(E11,0)+60, G11="EM90",EOMONTH(E11,0)+90, G11="OA15",E11+15, G11="OA30",E11+30, G11="OA60",E11+60)} -> 46181 | G11: =VLOOKUP(C11,Vendor_list!A:D,3,0) -> OA30 | H11: 243500 | I11: High | J11: Paid | K11: 46183 | L11: =IF(J11="Paid",K11,IF(J11="Open",F11,F11+INDEX(Vendor_list!$F$2:$F$16,MATCH(B11,Vendor_list!$B$2:$B$16,0))*Weekly_Cash_Flow_Summary!$B$9)) -> 46183
A12: AP-260011 | B12: =VLOOKUP(C12,Vendor_list!A:D,2,0) -> V00009 | C12: Bayridge Fabrication Inc. | D12: =VLOOKUP(C12,Vendor_list!A:D,4,0) -> B | E12: 46124 | F12: {=_xlfn.IFS(G12="EM15",EOMONTH(E12,0)+15, G12="EM30",EOMONTH(E12,0)+30, G12="EM45",EOMONTH(E12,0)+45, G12="EM60",EOMONTH(E12,0)+60, G12="EM90",EOMONTH(E12,0)+90, G12="OA15",E12+15, G12="OA30",E12+30, G12="OA60",E12+60)} -> 46184 | G12: =VLOOKUP(C12,Vendor_list!A:D,3,0) -> OA60 | H12: 101000 | I12: Medium | J12: Paid | K12: 46198 | L12: =IF(J12="Paid",K12,IF(J12="Open",F12,F12+INDEX(Vendor_list!$F$2:$F$16,MATCH(B12,Vendor_list!$B$2:$B$16,0))*Weekly_Cash_Flow_Summary!$B$9)) -> 46198
A13: AP-260012 | B13: =VLOOKUP(C13,Vendor_list!A:D,2,0) -> V00004 | C13: Redwood Packaging Co. | D13: =VLOOKUP(C13,Vendor_list!A:D,4,0) -> B | E13: 46158 | F13: {=_xlfn.IFS(G13="EM15",EOMONTH(E13,0)+15, G13="EM30",EOMONTH(E13,0)+30, G13="EM45",EOMONTH(E13,0)+45, G13="EM60",EOMONTH(E13,0)+60, G13="EM90",EOMONTH(E13,0)+90, G13="OA15",E13+15, G13="OA30",E13+30, G13="OA60",E13+60)} -> 46263 | G13: =VLOOKUP(C13,Vendor_list!A:D,3,0) -> EM90 | H13: 192000 | I13: Medium | J13: Open | L13: =IF(J13="Paid",K13,IF(J13="Open",F13,F13+INDEX(Vendor_list!$F$2:$F$16,MATCH(B13,Vendor_list!$B$2:$B$16,0))*Weekly_Cash_Flow_Summary!$B$9)) -> 46263
A14: AP-260013 | B14: =VLOOKUP(C14,Vendor_list!A:D,2,0) -> V00006 | C14: Vantage Point Materials | D14: =VLOOKUP(C14,Vendor_list!A:D,4,0) -> B | E14: 46230 | F14: {=_xlfn.IFS(G14="EM15",EOMONTH(E14,0)+15, G14="EM30",EOMONTH(E14,0)+30, G14="EM45",EOMONTH(E14,0)+45, G14="EM60",EOMONTH(E14,0)+60, G14="EM90",EOMONTH(E14,0)+90, G14="OA15",E14+15, G14="OA30",E14+30, G14="OA60",E14+60)} -> 46245 | G14: =VLOOKUP(C14,Vendor_list!A:D,3,0) -> OA15 | H14: 46500 | I14: Medium | J14: Open | L14: =IF(J14="Paid",K14,IF(J14="Open",F14,F14+INDEX(Vendor_list!$F$2:$F$16,MATCH(B14,Vendor_list!$B$2:$B$16,0))*Weekly_Cash_Flow_Summary!$B$9)) -> 46245
A15: AP-260014 | B15: =VLOOKUP(C15,Vendor_list!A:D,2,0) -> V00002 | C15: Coastal Line Logistics | D15: =VLOOKUP(C15,Vendor_list!A:D,4,0) -> C | E15: 46205 | F15: {=_xlfn.IFS(G15="EM15",EOMONTH(E15,0)+15, G15="EM30",EOMONTH(E15,0)+30, G15="EM45",EOMONTH(E15,0)+45, G15="EM60",EOMONTH(E15,0)+60, G15="EM90",EOMONTH(E15,0)+90, G15="OA15",E15+15, G15="OA30",E15+30, G15="OA60",E15+60)} -> 46324 | G15: =VLOOKUP(C15,Vendor_list!A:D,3,0) -> EM90 | H15: 95000 | I15: High | J15: Open | L15: =IF(J15="Paid",K15,IF(J15="Open",F15,F15+INDEX(Vendor_list!$F$2:$F$16,MATCH(B15,Vendor_list!$B$2:$B$16,0))*Weekly_Cash_Flow_Summary!$B$9)) -> 46324
A16: AP-260015 | B16: =VLOOKUP(C16,Vendor_list!A:D,2,0) -> V00005 | C16: Summit Ridge Components | D16: =VLOOKUP(C16,Vendor_list!A:D,4,0) -> A | E16: 46231 | F16: {=_xlfn.IFS(G16="EM15",EOMONTH(E16,0)+15, G16="EM30",EOMONTH(E16,0)+30, G16="EM45",EOMONTH(E16,0)+45, G16="EM60",EOMONTH(E16,0)+60, G16="EM90",EOMONTH(E16,0)+90, G16="OA15",E16+15, G16="OA30",E16+30, G16="OA60",E16+60)} -> 46249 | G16: =VLOOKUP(C16,Vendor_list!A:D,3,0) -> EM15 | H16: 144500 | I16: High | J16: Open | L16: =IF(J16="Paid",K16,IF(J16="Open",F16,F16+INDEX(Vendor_list!$F$2:$F$16,MATCH(B16,Vendor_list!$B$2:$B$16,0))*Weekly_Cash_Flow_Summary!$B$9)) -> 46249
A17: AP-260016 | B17: =VLOOKUP(C17,Vendor_list!A:D,2,0) -> V00010 | C17: Timberline Wholesale Goods | D17: =VLOOKUP(C17,Vendor_list!A:D,4,0) -> C | E17: 46223 | F17: {=_xlfn.IFS(G17="EM15",EOMONTH(E17,0)+15, G17="EM30",EOMONTH(E17,0)+30, G17="EM45",EOMONTH(E17,0)+45, G17="EM60",EOMONTH(E17,0)+60, G17="EM90",EOMONTH(E17,0)+90, G17="OA15",E17+15, G17="OA30",E17+30, G17="OA60",E17+60)} -> 46238 | G17: =VLOOKUP(C17,Vendor_list!A:D,3,0) -> OA15 | H17: 247500 | I17: Low | J17: Open | L17: =IF(J17="Paid",K17,IF(J17="Open",F17,F17+INDEX(Vendor_list!$F$2:$F$16,MATCH(B17,Vendor_list!$B$2:$B$16,0))*Weekly_Cash_Flow_Summary!$B$9)) -> 46238
A18: AP-260017 | B18: =VLOOKUP(C18,Vendor_list!A:D,2,0) -> V00004 | C18: Redwood Packaging Co. | D18: =VLOOKUP(C18,Vendor_list!A:D,4,0) -> B | E18: 46197 | F18: {=_xlfn.IFS(G18="EM15",EOMONTH(E18,0)+15, G18="EM30",EOMONTH(E18,0)+30, G18="EM45",EOMONTH(E18,0)+45, G18="EM60",EOMONTH(E18,0)+60, G18="EM90",EOMONTH(E18,0)+90, G18="OA15",E18+15, G18="OA30",E18+30, G18="OA60",E18+60)} -> 46293 | G18: =VLOOKUP(C18,Vendor_list!A:D,3,0) -> EM90 | H18: 119500 | I18: Medium | J18: Open | L18: =IF(J18="Paid",K18,IF(J18="Open",F18,F18+INDEX(Vendor_list!$F$2:$F$16,MATCH(B18,Vendor_list!$B$2:$B$16,0))*Weekly_Cash_Flow_Summary!$B$9)) -> 46293
A19: AP-260018 | B19: =VLOOKUP(C19,Vendor_list!A:D,2,0) -> V00008 | C19: Copperfield Industrial Supply | D19: =VLOOKUP(C19,Vendor_list!A:D,4,0) -> C | E19: 46173 | F19: {=_xlfn.IFS(G19="EM15",EOMONTH(E19,0)+15, G19="EM30",EOMONTH(E19,0)+30, G19="EM45",EOMONTH(E19,0)+45, G19="EM60",EOMONTH(E19,0)+60, G19="EM90",EOMONTH(E19,0)+90, G19="OA15",E19+15, G19="OA30",E19+30, G19="OA60",E19+60)} -> 46233 | G19: =VLOOKUP(C19,Vendor_list!A:D,3,0) -> EM60 | H19: 130000 | I19: Medium | J19: Open | L19: =IF(J19="Paid",K19,IF(J19="Open",F19,F19+INDEX(Vendor_list!$F$2:$F$16,MATCH(B19,Vendor_list!$B$2:$B$16,0))*Weekly_Cash_Flow_Summary!$B$9)) -> 46233
A20: AP-260019 | B20: =VLOOKUP(C20,Vendor_list!A:D,2,0) -> V00009 | C20: Bayridge Fabrication Inc. | D20: =VLOOKUP(C20,Vendor_list!A:D,4,0) -> B | E20: 46182 | F20: {=_xlfn.IFS(G20="EM15",EOMONTH(E20,0)+15, G20="EM30",EOMONTH(E20,0)+30, G20="EM45",EOMONTH(E20,0)+45, G20="EM60",EOMONTH(E20,0)+60, G20="EM90",EOMONTH(E20,0)+90, G20="OA15",E20+15, G20="OA30",E20+30, G20="OA60",E20+60)} -> 46242 | G20: =VLOOKUP(C20,Vendor_list!A:D,3,0) -> OA60 | H20: 107500 | I20: Medium | J20: Open | L20: =IF(J20="Paid",K20,IF(J20="Open",F20,F20+INDEX(Vendor_list!$F$2:$F$16,MATCH(B20,Vendor_list!$B$2:$B$16,0))*Weekly_Cash_Flow_Summary!$B$9)) -> 46242
A21: AP-260020 | B21: =VLOOKUP(C21,Vendor_list!A:D,2,0) -> V00002 | C21: Coastal Line Logistics | D21: =VLOOKUP(C21,Vendor_list!A:D,4,0) -> C | E21: 46162 | F21: {=_xlfn.IFS(G21="EM15",EOMONTH(E21,0)+15, G21="EM30",EOMONTH(E21,0)+30, G21="EM45",EOMONTH(E21,0)+45, G21="EM60",EOMONTH(E21,0)+60, G21="EM90",EOMONTH(E21,0)+90, G21="OA15",E21+15, G21="OA30",E21+30, G21="OA60",E21+60)} -> 46263 | G21: =VLOOKUP(C21,Vendor_list!A:D,3,0) -> EM90 | H21: 23000 | I21: High | J21: Open | L21: =IF(J21="Paid",K21,IF(J21="Open",F21,F21+INDEX(Vendor_list!$F$2:$F$16,MATCH(B21,Vendor_list!$B$2:$B$16,0))*Weekly_Cash_Flow_Summary!$B$9)) -> 46263
A22: AP-260021 | B22: =VLOOKUP(C22,Vendor_list!A:D,2,0) -> V00009 | C22: Bayridge Fabrication Inc. | D22: =VLOOKUP(C22,Vendor_list!A:D,4,0) -> B | E22: 46162 | F22: {=_xlfn.IFS(G22="EM15",EOMONTH(E22,0)+15, G22="EM30",EOMONTH(E22,0)+30, G22="EM45",EOMONTH(E22,0)+45, G22="EM60",EOMONTH(E22,0)+60, G22="EM90",EOMONTH(E22,0)+90, G22="OA15",E22+15, G22="OA30",E22+30, G22="OA60",E22+60)} -> 46222 | G22: =VLOOKUP(C22,Vendor_list!A:D,3,0) -> OA60 | H22: 138500 | I22: Medium | J22: Overdue | L22: =IF(J22="Paid",K22,IF(J22="Open",F22,F22+INDEX(Vendor_list!$F$2:$F$16,MATCH(B22,Vendor_list!$B$2:$B$16,0))*Weekly_Cash_Flow_Summary!$B$9)) -> 46229
A23: AP-260022 | B23: =VLOOKUP(C23,Vendor_list!A:D,2,0) -> V00003 | C23: Amberfield Textiles | D23: =VLOOKUP(C23,Vendor_list!A:D,4,0) -> C | E23: 46177 | F23: {=_xlfn.IFS(G23="EM15",EOMONTH(E23,0)+15, G23="EM30",EOMONTH(E23,0)+30, G23="EM45",EOMONTH(E23,0)+45, G23="EM60",EOMONTH(E23,0)+60, G23="EM90",EOMONTH(E23,0)+90, G23="OA15",E23+15, G23="OA30",E23+30, G23="OA60",E23+60)} -> 46207 | G23: =VLOOKUP(C23,Vendor_list!A:D,3,0) -> OA30 | H23: 289500 | I23: Medium | J23: Overdue | L23: =IF(J23="Paid",K23,IF(J23="Open",F23,F23+INDEX(Vendor_list!$F$2:$F$16,MATCH(B23,Vendor_list!$B$2:$B$16,0))*Weekly_Cash_Flow_Summary!$B$9)) -> 46214
A24: AP-260023 | B24: =VLOOKUP(C24,Vendor_list!A:D,2,0) -> V00010 | C24: Timberline Wholesale Goods | D24: =VLOOKUP(C24,Vendor_list!A:D,4,0) -> C | E24: 46164 | F24: {=_xlfn.IFS(G24="EM15",EOMONTH(E24,0)+15, G24="EM30",EOMONTH(E24,0)+30, G24="EM45",EOMONTH(E24,0)+45, G24="EM60",EOMONTH(E24,0)+60, G24="EM90",EOMONTH(E24,0)+90, G24="OA15",E24+15, G24="OA30",E24+30, G24="OA60",E24+60)} -> 46179 | G24: =VLOOKUP(C24,Vendor_list!A:D,3,0) -> OA15 | H24: 291500 | I24: Low | J24: Paid | K24: 46198 | L24: =IF(J24="Paid",K24,IF(J24="Open",F24,F24+INDEX(Vendor_list!$F$2:$F$16,MATCH(B24,Vendor_list!$B$2:$B$16,0))*Weekly_Cash_Flow_Summary!$B$9)) -> 46198
A25: AP-260024 | B25: =VLOOKUP(C25,Vendor_list!A:D,2,0) -> V00002 | C25: Coastal Line Logistics | D25: =VLOOKUP(C25,Vendor_list!A:D,4,0) -> C | E25: 46153 | F25: {=_xlfn.IFS(G25="EM15",EOMONTH(E25,0)+15, G25="EM30",EOMONTH(E25,0)+30, G25="EM45",EOMONTH(E25,0)+45, G25="EM60",EOMONTH(E25,0)+60, G25="EM90",EOMONTH(E25,0)+90, G25="OA15",E25+15, G25="OA30",E25+30, G25="OA60",E25+60)} -> 46263 | G25: =VLOOKUP(C25,Vendor_list!A:D,3,0) -> EM90 | H25: 276000 | I25: High | J25: Open | L25: =IF(J25="Paid",K25,IF(J25="Open",F25,F25+INDEX(Vendor_list!$F$2:$F$16,MATCH(B25,Vendor_list!$B$2:$B$16,0))*Weekly_Cash_Flow_Summary!$B$9)) -> 46263
A26: AP-260025 | B26: =VLOOKUP(C26,Vendor_list!A:D,2,0) -> V00005 | C26: Summit Ridge Components | D26: =VLOOKUP(C26,Vendor_list!A:D,4,0) -> A | E26: 46205 | F26: {=_xlfn.IFS(G26="EM15",EOMONTH(E26,0)+15, G26="EM30",EOMONTH(E26,0)+30, G26="EM45",EOMONTH(E26,0)+45, G26="EM60",EOMONTH(E26,0)+60, G26="EM90",EOMONTH(E26,0)+90, G26="OA15",E26+15, G26="OA30",E26+30, G26="OA60",E26+60)} -> 46249 | G26: =VLOOKUP(C26,Vendor_list!A:D,3,0) -> EM15 | H26: 213000 | I26: High | J26: Open | L26: =IF(J26="Paid",K26,IF(J26="Open",F26,F26+INDEX(Vendor_list!$F$2:$F$16,MATCH(B26,Vendor_list!$B$2:$B$16,0))*Weekly_Cash_Flow_Summary!$B$9)) -> 46249
A27: AP-260026 | B27: =VLOOKUP(C27,Vendor_list!A:D,2,0) -> V00015 | C27: Marbleton Supply Chain Co. | D27: =VLOOKUP(C27,Vendor_list!A:D,4,0) -> C | E27: 46167 | F27: {=_xlfn.IFS(G27="EM15",EOMONTH(E27,0)+15, G27="EM30",EOMONTH(E27,0)+30, G27="EM45",EOMONTH(E27,0)+45, G27="EM60",EOMONTH(E27,0)+60, G27="EM90",EOMONTH(E27,0)+90, G27="OA15",E27+15, G27="OA30",E27+30, G27="OA60",E27+60)} -> 46227 | G27: =VLOOKUP(C27,Vendor_list!A:D,3,0) -> OA60 | H27: 283500 | I27: Low | J27: Overdue | L27: =IF(J27="Paid",K27,IF(J27="Open",F27,F27+INDEX(Vendor_list!$F$2:$F$16,MATCH(B27,Vendor_list!$B$2:$B$16,0))*Weekly_Cash_Flow_Summary!$B$9)) -> 46242
A28: AP-260027 | B28: =VLOOKUP(C28,Vendor_list!A:D,2,0) -> V00009 | C28: Bayridge Fabrication Inc. | D28: =VLOOKUP(C28,Vendor_list!A:D,4,0) -> B | E28: 46181 | F28: {=_xlfn.IFS(G28="EM15",EOMONTH(E28,0)+15, G28="EM30",EOMONTH(E28,0)+30, G28="EM45",EOMONTH(E28,0)+45, G28="EM60",EOMONTH(E28,0)+60, G28="EM90",EOMONTH(E28,0)+90, G28="OA15",E28+15, G28="OA30",E28+30, G28="OA60",E28+60)} -> 46241 | G28: =VLOOKUP(C28,Vendor_list!A:D,3,0) -> OA60 | H28: 278000 | I28: Medium | J28: Open | L28: =IF(J28="Paid",K28,IF(J28="Open",F28,F28+INDEX(Vendor_list!$F$2:$F$16,MATCH(B28,Vendor_list!$B$2:$B$16,0))*Weekly_Cash_Flow_Summary!$B$9)) -> 46241
A29: AP-260028 | B29: =VLOOKUP(C29,Vendor_list!A:D,2,0) -> V00001 | C29: Granite Peak Manufacturing | D29: =VLOOKUP(C29,Vendor_list!A:D,4,0) -> A | E29: 46211 | F29: {=_xlfn.IFS(G29="EM15",EOMONTH(E29,0)+15, G29="EM30",EOMONTH(E29,0)+30, G29="EM45",EOMONTH(E29,0)+45, G29="EM60",EOMONTH(E29,0)+60, G29="EM90",EOMONTH(E29,0)+90, G29="OA15",E29+15, G29="OA30",E29+30, G29="OA60",E29+60)} -> 46241 | G29: =VLOOKUP(C29,Vendor_list!A:D,3,0) -> OA30 | H29: 50500 | I29: High | J29: Open | L29: =IF(J29="Paid",K29,IF(J29="Open",F29,F29+INDEX(Vendor_list!$F$2:$F$16,MATCH(B29,Vendor_list!$B$2:$B$16,0))*Weekly_Cash_Flow_Summary!$B$9)) -> 46241
A30: AP-260029 | B30: =VLOOKUP(C30,Vendor_list!A:D,2,0) -> V00004 | C30: Redwood Packaging Co. | D30: =VLOOKUP(C30,Vendor_list!A:D,4,0) -> B | E30: 46193 | F30: {=_xlfn.IFS(G30="EM15",EOMONTH(E30,0)+15, G30="EM30",EOMONTH(E30,0)+30, G30="EM45",EOMONTH(E30,0)+45, G30="EM60",EOMONTH(E30,0)+60, G30="EM90",EOMONTH(E30,0)+90, G30="OA15",E30+15, G30="OA30",E30+30, G30="OA60",E30+60)} -> 46293 | G30: =VLOOKUP(C30,Vendor_list!A:D,3,0) -> EM90 | H30: 272500 | I30: Medium | J30: Open | L30: =IF(J30="Paid",K30,IF(J30="Open",F30,F30+INDEX(Vendor_list!$F$2:$F$16,MATCH(B30,Vendor_list!$B$2:$B$16,0))*Weekly_Cash_Flow_Summary!$B$9)) -> 46293
A31: AP-260030 | B31: =VLOOKUP(C31,Vendor_list!A:D,2,0) -> V00014 | C31: Kestrel Logistics Group | D31: =VLOOKUP(C31,Vendor_list!A:D,4,0) -> C | E31: 46118 | F31: {=_xlfn.IFS(G31="EM15",EOMONTH(E31,0)+15, G31="EM30",EOMONTH(E31,0)+30, G31="EM45",EOMONTH(E31,0)+45, G31="EM60",EOMONTH(E31,0)+60, G31="EM90",EOMONTH(E31,0)+90, G31="OA15",E31+15, G31="OA30",E31+30, G31="OA60",E31+60)} -> 46133 | G31: =VLOOKUP(C31,Vendor_list!A:D,3,0) -> OA15 | H31: 92000 | I31: Low | J31: Paid | K31: 46152 | L31: =IF(J31="Paid",K31,IF(J31="Open",F31,F31+INDEX(Vendor_list!$F$2:$F$16,MATCH(B31,Vendor_list!$B$2:$B$16,0))*Weekly_Cash_Flow_Summary!$B$9)) -> 46152
A32: AP-260031 | B32: =VLOOKUP(C32,Vendor_list!A:D,2,0) -> V00006 | C32: Vantage Point Materials | D32: =VLOOKUP(C32,Vendor_list!A:D,4,0) -> B | E32: 46193 | F32: {=_xlfn.IFS(G32="EM15",EOMONTH(E32,0)+15, G32="EM30",EOMONTH(E32,0)+30, G32="EM45",EOMONTH(E32,0)+45, G32="EM60",EOMONTH(E32,0)+60, G32="EM90",EOMONTH(E32,0)+90, G32="OA15",E32+15, G32="OA30",E32+30, G32="OA60",E32+60)} -> 46208 | G32: =VLOOKUP(C32,Vendor_list!A:D,3,0) -> OA15 | H32: 87500 | I32: Medium | J32: Paid | K32: 46213 | L32: =IF(J32="Paid",K32,IF(J32="Open",F32,F32+INDEX(Vendor_list!$F$2:$F$16,MATCH(B32,Vendor_list!$B$2:$B$16,0))*Weekly_Cash_Flow_Summary!$B$9)) -> 46213
A33: AP-260032 | B33: =VLOOKUP(C33,Vendor_list!A:D,2,0) -> V00012 | C33: Starling Print & Packaging | D33: =VLOOKUP(C33,Vendor_list!A:D,4,0) -> B | E33: 46145 | F33: {=_xlfn.IFS(G33="EM15",EOMONTH(E33,0)+15, G33="EM30",EOMONTH(E33,0)+30, G33="EM45",EOMONTH(E33,0)+45, G33="EM60",EOMONTH(E33,0)+60, G33="EM90",EOMONTH(E33,0)+90, G33="OA15",E33+15, G33="OA30",E33+30, G33="OA60",E33+60)} -> 46160 | G33: =VLOOKUP(C33,Vendor_list!A:D,3,0) -> OA15 | H33: 178000 | I33: Low | J33: Paid | K33: 46183 | L33: =IF(J33="Paid",K33,IF(J33="Open",F33,F33+INDEX(Vendor_list!$F$2:$F$16,MATCH(B33,Vendor_list!$B$2:$B$16,0))*Weekly_Cash_Flow_Summary!$B$9)) -> 46183
A34: AP-260033 | B34: =VLOOKUP(C34,Vendor_list!A:D,2,0) -> V00006 | C34: Vantage Point Materials | D34: =VLOOKUP(C34,Vendor_list!A:D,4,0) -> B | E34: 46118 | F34: {=_xlfn.IFS(G34="EM15",EOMONTH(E34,0)+15, G34="EM30",EOMONTH(E34,0)+30, G34="EM45",EOMONTH(E34,0)+45, G34="EM60",EOMONTH(E34,0)+60, G34="EM90",EOMONTH(E34,0)+90, G34="OA15",E34+15, G34="OA30",E34+30, G34="OA60",E34+60)} -> 46133 | G34: =VLOOKUP(C34,Vendor_list!A:D,3,0) -> OA15 | H34: 26000 | I34: Medium | J34: Paid | K34: 46152 | L34: =IF(J34="Paid",K34,IF(J34="Open",F34,F34+INDEX(Vendor_list!$F$2:$F$16,MATCH(B34,Vendor_list!$B$2:$B$16,0))*Weekly_Cash_Flow_Summary!$B$9)) -> 46152
A35: AP-260034 | B35: =VLOOKUP(C35,Vendor_list!A:D,2,0) -> V00002 | C35: Coastal Line Logistics | D35: =VLOOKUP(C35,Vendor_list!A:D,4,0) -> C | E35: 46142 | F35: {=_xlfn.IFS(G35="EM15",EOMONTH(E35,0)+15, G35="EM30",EOMONTH(E35,0)+30, G35="EM45",EOMONTH(E35,0)+45, G35="EM60",EOMONTH(E35,0)+60, G35="EM90",EOMONTH(E35,0)+90, G35="OA15",E35+15, G35="OA30",E35+30, G35="OA60",E35+60)} -> 46232 | G35: =VLOOKUP(C35,Vendor_list!A:D,3,0) -> EM90 | H35: 69500 | I35: High | J35: Overdue | L35: =IF(J35="Paid",K35,IF(J35="Open",F35,F35+INDEX(Vendor_list!$F$2:$F$16,MATCH(B35,Vendor_list!$B$2:$B$16,0))*Weekly_Cash_Flow_Summary!$B$9)) -> 46234
A36: AP-260035 | B36: =VLOOKUP(C36,Vendor_list!A:D,2,0) -> V00013 | C36: Ashford Raw Materials Ltd. | D36: =VLOOKUP(C36,Vendor_list!A:D,4,0) -> B | E36: 46178 | F36: {=_xlfn.IFS(G36="EM15",EOMONTH(E36,0)+15, G36="EM30",EOMONTH(E36,0)+30, G36="EM45",EOMONTH(E36,0)+45, G36="EM60",EOMONTH(E36,0)+60, G36="EM90",EOMONTH(E36,0)+90, G36="OA15",E36+15, G36="OA30",E36+30, G36="OA60",E36+60)} -> 46208 | G36: =VLOOKUP(C36,Vendor_list!A:D,3,0) -> OA30 | H36: 59500 | I36: Low | J36: Paid | K36: 46228 | L36: =IF(J36="Paid",K36,IF(J36="Open",F36,F36+INDEX(Vendor_list!$F$2:$F$16,MATCH(B36,Vendor_list!$B$2:$B$16,0))*Weekly_Cash_Flow_Summary!$B$9)) -> 46228
A37: AP-260036 | B37: =VLOOKUP(C37,Vendor_list!A:D,2,0) -> V00011 | C37: Highcastle Equipment Co. | D37: =VLOOKUP(C37,Vendor_list!A:D,4,0) -> C | E37: 46203 | F37: {=_xlfn.IFS(G37="EM15",EOMONTH(E37,0)+15, G37="EM30",EOMONTH(E37,0)+30, G37="EM45",EOMONTH(E37,0)+45, G37="EM60",EOMONTH(E37,0)+60, G37="EM90",EOMONTH(E37,0)+90, G37="OA15",E37+15, G37="OA30",E37+30, G37="OA60",E37+60)} -> 46293 | G37: =VLOOKUP(C37,Vendor_list!A:D,3,0) -> EM90 | H37: 192000 | I37: High | J37: Open | L37: =IF(J37="Paid",K37,IF(J37="Open",F37,F37+INDEX(Vendor_list!$F$2:$F$16,MATCH(B37,Vendor_list!$B$2:$B$16,0))*Weekly_Cash_Flow_Summary!$B$9)) -> 46293
A38: AP-260037 | B38: =VLOOKUP(C38,Vendor_list!A:D,2,0) -> V00007 | C38: Northline Freight Services | D38: =VLOOKUP(C38,Vendor_list!A:D,4,0) -> A | E38: 46114 | F38: {=_xlfn.IFS(G38="EM15",EOMONTH(E38,0)+15, G38="EM30",EOMONTH(E38,0)+30, G38="EM45",EOMONTH(E38,0)+45, G38="EM60",EOMONTH(E38,0)+60, G38="EM90",EOMONTH(E38,0)+90, G38="OA15",E38+15, G38="OA30",E38+30, G38="OA60",E38+60)} -> 46129 | G38: =VLOOKUP(C38,Vendor_list!A:D,3,0) -> OA15 | H38: 128500 | I38: High | J38: Paid | K38: 46137 | L38: =IF(J38="Paid",K38,IF(J38="Open",F38,F38+INDEX(Vendor_list!$F$2:$F$16,MATCH(B38,Vendor_list!$B$2:$B$16,0))*Weekly_Cash_Flow_Summary!$B$9)) -> 46137
A39: AP-260038 | B39: =VLOOKUP(C39,Vendor_list!A:D,2,0) -> V00014 | C39: Kestrel Logistics Group | D39: =VLOOKUP(C39,Vendor_list!A:D,4,0) -> C | E39: 46186 | F39: {=_xlfn.IFS(G39="EM15",EOMONTH(E39,0)+15, G39="EM30",EOMONTH(E39,0)+30, G39="EM45",EOMONTH(E39,0)+45, G39="EM60",EOMONTH(E39,0)+60, G39="EM90",EOMONTH(E39,0)+90, G39="OA15",E39+15, G39="OA30",E39+30, G39="OA60",E39+60)} -> 46201 | G39: =VLOOKUP(C39,Vendor_list!A:D,3,0) -> OA15 | H39: 206500 | I39: Low | J39: Paid | K39: 46228 | L39: =IF(J39="Paid",K39,IF(J39="Open",F39,F39+INDEX(Vendor_list!$F$2:$F$16,MATCH(B39,Vendor_list!$B$2:$B$16,0))*Weekly_Cash_Flow_Summary!$B$9)) -> 46228
A40: AP-260039 | B40: =VLOOKUP(C40,Vendor_list!A:D,2,0) -> V00004 | C40: Redwood Packaging Co. | D40: =VLOOKUP(C40,Vendor_list!A:D,4,0) -> B | E40: 46172 | F40: {=_xlfn.IFS(G40="EM15",EOMONTH(E40,0)+15, G40="EM30",EOMONTH(E40,0)+30, G40="EM45",EOMONTH(E40,0)+45, G40="EM60",EOMONTH(E40,0)+60, G40="EM90",EOMONTH(E40,0)+90, G40="OA15",E40+15, G40="OA30",E40+30, G40="OA60",E40+60)} -> 46263 | G40: =VLOOKUP(C40,Vendor_list!A:D,3,0) -> EM90 | H40: 258500 | I40: Medium | J40: Open | L40: =IF(J40="Paid",K40,IF(J40="Open",F40,F40+INDEX(Vendor_list!$F$2:$F$16,MATCH(B40,Vendor_list!$B$2:$B$16,0))*Weekly_Cash_Flow_Summary!$B$9)) -> 46263
...

Sheet Customer_list
A1: Customer_Name | B1: Customer_Code | C1: Payment_Terms | D1: Department | E1: Payment Habit | F1: Credit Limit | G1: Collection_Probability | H1: Typical_Delay_Days | J1: Habit | K1: Base_Probability | L1: Typical_Delay_Days
A2: Silverline Retail Group | B2: C00001 | C2: EM15 | D2: C | E2: Good | F2: 1150000 | G2: =INDEX($K$2:$K$4,MATCH(E2,$J$2:$J$4,0)) -> 0.97 | H2: =INDEX($L$2:$L$4,MATCH(E2,$J$2:$J$4,0)) -> 3 | J2: Good | K2: 0.97 | L2: 3
A3: Northgate Commerce Co. | B3: C00002 | C3: OA60 | D3: B | E3: Average | F3: 350000 | G3: =INDEX($K$2:$K$4,MATCH(E3,$J$2:$J$4,0)) -> 0.9 | H3: =INDEX($L$2:$L$4,MATCH(E3,$J$2:$J$4,0)) -> 10 | J3: Average | K3: 0.9 | L3: 10
A4: BluePeak Distributors | B4: C00003 | C4: EM60 | D4: A | E4: Good | F4: 550000 | G4: =INDEX($K$2:$K$4,MATCH(E4,$J$2:$J$4,0)) -> 0.97 | H4: =INDEX($L$2:$L$4,MATCH(E4,$J$2:$J$4,0)) -> 3 | J4: Poor | K4: 0.75 | L4: 25
A5: Harborview Trading Ltd. | B5: C00004 | C5: EM60 | D5: B | E5: Average | F5: 550000 | G5: =INDEX($K$2:$K$4,MATCH(E5,$J$2:$J$4,0)) -> 0.9 | H5: =INDEX($L$2:$L$4,MATCH(E5,$J$2:$J$4,0)) -> 10
A6: Crestwood Merchandise Inc. | B6: C00005 | C6: OA30 | D6: C | E6: Poor | F6: 250000 | G6: =INDEX($K$2:$K$4,MATCH(E6,$J$2:$J$4,0)) -> 0.75 | H6: =INDEX($L$2:$L$4,MATCH(E6,$J$2:$J$4,0)) -> 25
A7: Meadowbrook Supply Co. | B7: C00006 | C7: EM60 | D7: B | E7: Average | F7: 500000 | G7: =INDEX($K$2:$K$4,MATCH(E7,$J$2:$J$4,0)) -> 0.9 | H7: =INDEX($L$2:$L$4,MATCH(E7,$J$2:$J$4,0)) -> 10
A8: Ironstone Enterprises | B8: C00007 | C8: EM30 | D8: A | E8: Good | F8: 650000 | G8: =INDEX($K$2:$K$4,MATCH(E8,$J$2:$J$4,0)) -> 0.97 | H8: =INDEX($L$2:$L$4,MATCH(E8,$J$2:$J$4,0)) -> 3
A9: Sunridge Retail Partners | B9: C00008 | C9: OA30 | D9: B | E9: Average | F9: 350000 | G9: =INDEX($K$2:$K$4,MATCH(E9,$J$2:$J$4,0)) -> 0.9 | H9: =INDEX($L$2:$L$4,MATCH(E9,$J$2:$J$4,0)) -> 10
A10: Westfall Commercial Group | B10: C00009 | C10: EM30 | D10: A | E10: Average | F10: 350000 | G10: =INDEX($K$2:$K$4,MATCH(E10,$J$2:$J$4,0)) -> 0.9 | H10: =INDEX($L$2:$L$4,MATCH(E10,$J$2:$J$4,0)) -> 10
A11: Oakhaven Trading Co. | B11: C00010 | C11: OA30 | D11: A | E11: Good | F11: 1100000 | G11: =INDEX($K$2:$K$4,MATCH(E11,$J$2:$J$4,0)) -> 0.97 | H11: =INDEX($L$2:$L$4,MATCH(E11,$J$2:$J$4,0)) -> 3
